#VRML_SIM R2023b utf8

EXTERNPROTO "https://raw.githubusercontent.com/cyberbotics/webots/R2023b/projects/appearances/protos/Asphalt.proto"
EXTERNPROTO "https://raw.githubusercontent.com/cyberbotics/webots/R2023b/projects/objects/backgrounds/protos/TexturedBackground.proto"
EXTERNPROTO "https://raw.githubusercontent.com/cyberbotics/webots/R2023b/projects/objects/backgrounds/protos/TexturedBackgroundLight.proto"
EXTERNPROTO "https://raw.githubusercontent.com/cyberbotics/webots/R2023b/projects/objects/floors/protos/UnevenTerrain.proto"

WorldInfo {
}
Viewpoint {
  orientation -0.16112916115870687 0.23754703422539597 0.9579189944640465 1.232303144704157
  position -15.522143121954265 -48.2013297214486 18.186250829500228
}
TexturedBackground {
}
TexturedBackgroundLight {
}
Robot {
  translation 5.880028935410168 -0.02786985309757497 3.6600511366515396
  rotation 0.8185157370825851 -0.5734727314111703 0.03407366249707101 0.0792897196974108
  children [
    DistanceSensor {
      name "ds"
    }
    InertialUnit {
    }
    DEF torso Shape {
      appearance PBRAppearance {
        baseColor 0.6 0.6 1
        metalness 0
      }
      geometry Box {
        size 1 1 0.2
      }
    }
    DEF wheel HingeJoint {
      jointParameters HingeJointParameters {
        position 32.80000698190058
        axis 0 1 0
        anchor -0.3 -0.577883 -0.0631591
      }
      device [
        RotationalMotor {
          name "motor1"
        }
      ]
      endPoint Solid {
        translation -0.3 -0.577883 -0.0631591
        rotation 0.6431591592629291 -0.5497480736653062 -0.5330322235639109 4.312968773334345
        children [
          DEF wheel_body Shape {
            appearance Asphalt {
            }
            geometry Cylinder {
              height 0.2
              radius 0.18
            }
          }
        ]
        boundingObject USE wheel_body
        physics DEF phy1 Physics {
          mass 1
        }
      }
    }
    DEF wheel HingeJoint {
      jointParameters HingeJointParameters {
        position 32.796778691902645
        axis 0 1 0
        anchor 0.3 -0.577883 -0.0631591
      }
      device [
        RotationalMotor {
          name "motor2"
        }
      ]
      endPoint Solid {
        translation 0.3 -0.577883 -0.0631591
        rotation 0.6443980131518401 -0.5489997976742277 -0.5323066999386893 4.3147423123404245
        children [
          DEF wheel_body Shape {
            appearance Asphalt {
            }
            geometry Cylinder {
              height 0.2
              radius 0.18
            }
          }
        ]
        name "solid(1)"
        boundingObject USE wheel_body
        physics DEF phy1 Physics {
          mass 1
        }
      }
    }
    DEF wheel HingeJoint {
      jointParameters HingeJointParameters {
        position 32.799173551101674
        axis 0 1 0
        anchor 0.3 0.577883 -0.0631591
      }
      device [
        RotationalMotor {
          name "motor3"
        }
      ]
      endPoint Solid {
        translation 0.3 0.577883 -0.0631591
        rotation 0.6434790095463356 -0.5495551173804777 -0.5328451343816478 4.313426869913458
        children [
          DEF wheel_body Shape {
            appearance Asphalt {
            }
            geometry Cylinder {
              height 0.2
              radius 0.18
            }
          }
        ]
        name "solid(2)"
        boundingObject USE wheel_body
        physics DEF phy1 Physics {
          mass 1
        }
      }
    }
    DEF wheel HingeJoint {
      jointParameters HingeJointParameters {
        position 32.80034134409848
        axis 0 1 0
        anchor -0.3 0.577883 -0.0631591
      }
      device [
        RotationalMotor {
          name "motor4"
        }
      ]
      endPoint Solid {
        translation -0.3 0.577883 -0.0631591
        rotation 0.6430308350332116 -0.5498254419143974 -0.533107239324442 4.312784945424943
        children [
          DEF wheel_body Shape {
            appearance Asphalt {
            }
            geometry Cylinder {
              height 0.2
              radius 0.18
            }
          }
        ]
        name "solid(3)"
        boundingObject USE wheel_body
        physics DEF phy1 Physics {
          mass 1
        }
      }
    }
  ]
  boundingObject USE torso
  physics USE phy1
  controller "my_controller"
}
UnevenTerrain {
}
